Workbook

Sheet Sheet1
A1: brand
A2: 90210
A3: Ace Club
A4: Admiral
A5: After hours
A6: Alamo
A7: Alas
A8: Amsterdam
A9: Anchor
A10: Aristocrat
A11: Armada
A12: Ashford Blue
A13: AX Full Flavor
A14: B&B (Bulls & Bears)
... A287: XO
A288: ="99 " -> 99
A289: Action
A290: Bahrein
A291: Cali
A292: Catalina
A293: Denver
A294: Dos
A295: Ejecutivos
A296: Encanto
A297: H. Upmann
A298: Heris
A299: Iplay
A300: J&J
... A322: Studio54

Sheet RMF
B2: MARCA | C2: RMF 2023 | D2: RMF 2022 | E2: RMF 2021 | F2: RMF 2020 | G2: RMF 2019 | H2: RMF 2018 | I2: ALERTA SANITARIA (SI APARECE LA MARCA, NO APARECE) | J2: Ubicación (2023) | K2: Anterior (2017-19) | L2: Comparación | M2: LEGAL 2023 | N2: LEGAL 2017-19 | O2: Comparación
A3: {1 | B3: 90210 | C3: =IF(ISERROR(LOOKUP(2^15,SEARCH(B3,'2023'!$B$3:$B$1734,1),'2023'!$A$3:$A$1734)),"NO","SI") -> NO | D3: =IF(ISERROR(LOOKUP(2^15,SEARCH(B3,'2022'!$B$2:$B$1591,1),'2022'!$A$2:$A$1591)),"NO","SI") -> NO | E3: =IF(ISERROR(LOOKUP(2^15,SEARCH(B3,'2021'!$B$2:$B$1494,1),'2021'!$A$2:$A$1494)),"NO","SI") -> NO | F3: =IF(ISERROR(LOOKUP(2^15,SEARCH(B3,'2020'!$B$2:$B$1278,1),'2020'!$A$2:$A$1278)),"NO","SI") -> NO | G3: =IF(ISERROR(LOOKUP(2^15,SEARCH(B3,'2019'!$B$2:$B$1108,1),'2019'!$A$2:$A$1108)),"NO","SI") -> NO | H3: =IF(ISERROR(LOOKUP(2^15,SEARCH(B3,'2018'!$B$1:$B$1047,1),'2018'!$A$1:$A$1047)),"NO","SI") -> NO | I3: =IF(ISERROR(LOOKUP(2^15,SEARCH(B3,'ALERTA SANITARIA'!$B$2:$B$269,1),'2018'!$A$1:$A$1047)),"NO","SI") -> SI | J3: =IF(AND(C3="NO", I3="NO"), "Ninguno",IF(AND(C3="NO", I3="SI"), "COFEPRIS",IF(AND(C3="SI",I3="NO"),"DOF","AMBOS"))) -> COFEPRIS | K3: {=IFERROR(INDEX(Anterior!$C$1:$D$323,MATCH(B3,Anterior!$B$2:$B$323,0)+1,2),0)} -> COFEPRIS | L3: =IF(K3=J3,"coinciden",IF(K3=0,"Nuevo","Discrepan")) -> coinciden | M3: NO
A4: {2 | B4: Ace Club | C4: =IF(ISERROR(LOOKUP(2^15,SEARCH(B4,'2023'!$B$3:$B$1734,1),'2023'!$A$3:$A$1734)),"NO","SI") -> NO | D4: =IF(ISERROR(LOOKUP(2^15,SEARCH(B4,'2022'!$B$2:$B$1591,1),'2022'!$A$2:$A$1591)),"NO","SI") -> NO | E4: =IF(ISERROR(LOOKUP(2^15,SEARCH(B4,'2021'!$B$2:$B$1494,1),'2021'!$A$2:$A$1494)),"NO","SI") -> NO | F4: =IF(ISERROR(LOOKUP(2^15,SEARCH(B4,'2020'!$B$2:$B$1278,1),'2020'!$A$2:$A$1278)),"NO","SI") -> NO | G4: =IF(ISERROR(LOOKUP(2^15,SEARCH(B4,'2019'!$B$2:$B$1108,1),'2019'!$A$2:$A$1108)),"NO","SI") -> NO | H4: =IF(ISERROR(LOOKUP(2^15,SEARCH(B4,'2018'!$B$1:$B$1047,1),'2018'!$A$1:$A$1047)),"NO","SI") -> NO | I4: =IF(ISERROR(LOOKUP(2^15,SEARCH(B4,'ALERTA SANITARIA'!$B$2:$B$269,1),'2018'!$A$1:$A$1047)),"NO","SI") -> SI | J4: =IF(AND(C4="NO", I4="NO"), "Ninguno",IF(AND(C4="NO", I4="SI"), "COFEPRIS",IF(AND(C4="SI",I4="NO"),"DOF","AMBOS"))) -> COFEPRIS | K4: {=IFERROR(INDEX(Anterior!$C$1:$D$323,MATCH(B4,Anterior!$B$2:$B$323,0)+1,2),0)} -> COFEPRIS | L4: =IF(K4=J4,"coinciden",IF(K4=0,"Nuevo","Discrepan")) -> coinciden | M4: NO
A5: {3 | B5: Admiral | C5: =IF(ISERROR(LOOKUP(2^15,SEARCH(B5,'2023'!$B$3:$B$1734,1),'2023'!$A$3:$A$1734)),"NO","SI") -> NO | D5: =IF(ISERROR(LOOKUP(2^15,SEARCH(B5,'2022'!$B$2:$B$1591,1),'2022'!$A$2:$A$1591)),"NO","SI") -> NO | E5: =IF(ISERROR(LOOKUP(2^15,SEARCH(B5,'2021'!$B$2:$B$1494,1),'2021'!$A$2:$A$1494)),"NO","SI") -> NO | F5: =IF(ISERROR(LOOKUP(2^15,SEARCH(B5,'2020'!$B$2:$B$1278,1),'2020'!$A$2:$A$1278)),"NO","SI") -> NO | G5: =IF(ISERROR(LOOKUP(2^15,SEARCH(B5,'2019'!$B$2:$B$1108,1),'2019'!$A$2:$A$1108)),"NO","SI") -> NO | H5: =IF(ISERROR(LOOKUP(2^15,SEARCH(B5,'2018'!$B$1:$B$1047,1),'2018'!$A$1:$A$1047)),"NO","SI") -> NO | I5: =IF(ISERROR(LOOKUP(2^15,SEARCH(B5,'ALERTA SANITARIA'!$B$2:$B$269,1),'2018'!$A$1:$A$1047)),"NO","SI") -> SI | J5: =IF(AND(C5="NO", I5="NO"), "Ninguno",IF(AND(C5="NO", I5="SI"), "COFEPRIS",IF(AND(C5="SI",I5="NO"),"DOF","AMBOS"))) -> COFEPRIS | K5: {=IFERROR(INDEX(Anterior!$C$1:$D$323,MATCH(B5,Anterior!$B$2:$B$323,0)+1,2),0)} -> COFEPRIS | L5: =IF(K5=J5,"coinciden",IF(K5=0,"Nuevo","Discrepan")) -> coinciden | M5: NO
A6: {4 | B6: After hours | C6: =IF(ISERROR(LOOKUP(2^15,SEARCH(B6,'2023'!$B$3:$B$1734,1),'2023'!$A$3:$A$1734)),"NO","SI") -> NO | D6: =IF(ISERROR(LOOKUP(2^15,SEARCH(B6,'2022'!$B$2:$B$1591,1),'2022'!$A$2:$A$1591)),"NO","SI") -> NO | E6: =IF(ISERROR(LOOKUP(2^15,SEARCH(B6,'2021'!$B$2:$B$1494,1),'2021'!$A$2:$A$1494)),"NO","SI") -> NO | F6: =IF(ISERROR(LOOKUP(2^15,SEARCH(B6,'2020'!$B$2:$B$1278,1),'2020'!$A$2:$A$1278)),"NO","SI") -> NO | G6: =IF(ISERROR(LOOKUP(2^15,SEARCH(B6,'2019'!$B$2:$B$1108,1),'2019'!$A$2:$A$1108)),"NO","SI") -> NO | H6: =IF(ISERROR(LOOKUP(2^15,SEARCH(B6,'2018'!$B$1:$B$1047,1),'2018'!$A$1:$A$1047)),"NO","SI") -> NO | I6: =IF(ISERROR(LOOKUP(2^15,SEARCH(B6,'ALERTA SANITARIA'!$B$2:$B$269,1),'2018'!$A$1:$A$1047)),"NO","SI") -> SI | J6: =IF(AND(C6="NO", I6="NO"), "Ninguno",IF(AND(C6="NO", I6="SI"), "COFEPRIS",IF(AND(C6="SI",I6="NO"),"DOF","AMBOS"))) -> COFEPRIS | K6: {=IFERROR(INDEX(Anterior!$C$1:$D$323,MATCH(B6,Anterior!$B$2:$B$323,0)+1,2),0)} -> COFEPRIS | L6: =IF(K6=J6,"coinciden",IF(K6=0,"Nuevo","Discrepan")) -> coinciden | M6: NO
A7: {5 | B7: Alamo | C7: =IF(ISERROR(LOOKUP(2^15,SEARCH(B7,'2023'!$B$3:$B$1734,1),'2023'!$A$3:$A$1734)),"NO","SI") -> NO | D7: =IF(ISERROR(LOOKUP(2^15,SEARCH(B7,'2022'!$B$2:$B$1591,1),'2022'!$A$2:$A$1591)),"NO","SI") -> NO | E7: =IF(ISERROR(LOOKUP(2^15,SEARCH(B7,'2021'!$B$2:$B$1494,1),'2021'!$A$2:$A$1494)),"NO","SI") -> NO | F7: =IF(ISERROR(LOOKUP(2^15,SEARCH(B7,'2020'!$B$2:$B$1278,1),'2020'!$A$2:$A$1278)),"NO","SI") -> NO | G7: =IF(ISERROR(LOOKUP(2^15,SEARCH(B7,'2019'!$B$2:$B$1108,1),'2019'!$A$2:$A$1108)),"NO","SI") -> NO | H7: =IF(ISERROR(LOOKUP(2^15,SEARCH(B7,'2018'!$B$1:$B$1047,1),'2018'!$A$1:$A$1047)),"NO","SI") -> NO | I7: =IF(ISERROR(LOOKUP(2^15,SEARCH(B7,'ALERTA SANITARIA'!$B$2:$B$269,1),'2018'!$A$1:$A$1047)),"NO","SI") -> SI | J7: =IF(AND(C7="NO", I7="NO"), "Ninguno",IF(AND(C7="NO", I7="SI"), "COFEPRIS",IF(AND(C7="SI",I7="NO"),"DOF","AMBOS"))) -> COFEPRIS | K7: {=IFERROR(INDEX(Anterior!$C$1:$D$323,MATCH(B7,Anterior!$B$2:$B$323,0)+1,2),0)} -> COFEPRIS | L7: =IF(K7=J7,"coinciden",IF(K7=0,"Nuevo","Discrepan")) -> coinciden | M7: NO
A8: {6 | B8: Alas | C8: =IF(ISERROR(LOOKUP(2^15,SEARCH(B8,'2023'!$B$3:$B$1734,1),'2023'!$A$3:$A$1734)),"NO","SI") -> SI | D8: =IF(ISERROR(LOOKUP(2^15,SEARCH(B8,'2022'!$B$2:$B$1591,1),'2022'!$A$2:$A$1591)),"NO","SI") -> SI | E8: =IF(ISERROR(LOOKUP(2^15,SEARCH(B8,'2021'!$B$2:$B$1494,1),'2021'!$A$2:$A$1494)),"NO","SI") -> SI | F8: =IF(ISERROR(LOOKUP(2^15,SEARCH(B8,'2020'!$B$2:$B$1278,1),'2020'!$A$2:$A$1278)),"NO","SI") -> SI | G8: =IF(ISERROR(LOOKUP(2^15,SEARCH(B8,'2019'!$B$2:$B$1108,1),'2019'!$A$2:$A$1108)),"NO","SI") -> SI | H8: =IF(ISERROR(LOOKUP(2^15,SEARCH(B8,'2018'!$B$1:$B$1047,1),'2018'!$A$1:$A$1047)),"NO","SI") -> SI | I8: =IF(ISERROR(LOOKUP(2^15,SEARCH(B8,'ALERTA SANITARIA'!$B$2:$B$269,1),'2018'!$A$1:$A$1047)),"NO","SI") -> NO | J8: =IF(AND(C8="NO", I8="NO"), "Ninguno",IF(AND(C8="NO", I8="SI"), "COFEPRIS",IF(AND(C8="SI",I8="NO"),"DOF","AMBOS"))) -> DOF | K8: {=IFERROR(INDEX(Anterior!$C$1:$D$323,MATCH(B8,Anterior!$B$2:$B$323,0)+1,2),0)} -> DOF | L8: =IF(K8=J8,"coinciden",IF(K8=0,"Nuevo","Discrepan")) -> coinciden | M8: SI
A9: {7 | B9: Amsterdam | C9: =IF(ISERROR(LOOKUP(2^15,SEARCH(B9,'2023'!$B$3:$B$1734,1),'2023'!$A$3:$A$1734)),"NO","SI") -> NO | D9: =IF(ISERROR(LOOKUP(2^15,SEARCH(B9,'2022'!$B$2:$B$1591,1),'2022'!$A$2:$A$1591)),"NO","SI") -> NO | E9: =IF(ISERROR(LOOKUP(2^15,SEARCH(B9,'2021'!$B$2:$B$1494,1),'2021'!$A$2:$A$1494)),"NO","SI") -> NO | F9: =IF(ISERROR(LOOKUP(2^15,SEARCH(B9,'2020'!$B$2:$B$1278,1),'2020'!$A$2:$A$1278)),"NO","SI") -> NO | G9: =IF(ISERROR(LOOKUP(2^15,SEARCH(B9,'2019'!$B$2:$B$1108,1),'2019'!$A$2:$A$1108)),"NO","SI") -> NO | H9: =IF(ISERROR(LOOKUP(2^15,SEARCH(B9,'2018'!$B$1:$B$1047,1),'2018'!$A$1:$A$1047)),"NO","SI") -> NO | I9: =IF(ISERROR(LOOKUP(2^15,SEARCH(B9,'ALERTA SANITARIA'!$B$2:$B$269,1),'2018'!$A$1:$A$1047)),"NO","SI") -> SI | J9: =IF(AND(C9="NO", I9="NO"), "Ninguno",IF(AND(C9="NO", I9="SI"), "COFEPRIS",IF(AND(C9="SI",I9="NO"),"DOF","AMBOS"))) -> COFEPRIS | K9: {=IFERROR(INDEX(Anterior!$C$1:$D$323,MATCH(B9,Anterior!$B$2:$B$323,0)+1,2),0)} -> COFEPRIS | L9: =IF(K9=J9,"coinciden",IF(K9=0,"Nuevo","Discrepan")) -> coinciden
A10: {8 | B10: Anchor | C10: =IF(ISERROR(LOOKUP(2^15,SEARCH(B10,'2023'!$B$3:$B$1734,1),'2023'!$A$3:$A$1734)),"NO","SI") -> NO | D10: =IF(ISERROR(LOOKUP(2^15,SEARCH(B10,'2022'!$B$2:$B$1591,1),'2022'!$A$2:$A$1591)),"NO","SI") -> NO | E10: =IF(ISERROR(LOOKUP(2^15,SEARCH(B10,'2021'!$B$2:$B$1494,1),'2021'!$A$2:$A$1494)),"NO","SI") -> NO | F10: =IF(ISERROR(LOOKUP(2^15,SEARCH(B10,'2020'!$B$2:$B$1278,1),'2020'!$A$2:$A$1278)),"NO","SI") -> NO | G10: =IF(ISERROR(LOOKUP(2^15,SEARCH(B10,'2019'!$B$2:$B$1108,1),'2019'!$A$2:$A$1108)),"NO","SI") -> NO | H10: =IF(ISERROR(LOOKUP(2^15,SEARCH(B10,'2018'!$B$1:$B$1047,1),'2018'!$A$1:$A$1047)),"NO","SI") -> NO | I10: =IF(ISERROR(LOOKUP(2^15,SEARCH(B10,'ALERTA SANITARIA'!$B$2:$B$269,1),'2018'!$A$1:$A$1047)),"NO","SI") -> SI | J10: =IF(AND(C10="NO", I10="NO"), "Ninguno",IF(AND(C10="NO", I10="SI"), "COFEPRIS",IF(AND(C10="SI",I10="NO"),"DOF","AMBOS"))) -> COFEPRIS | K10: {=IFERROR(INDEX(Anterior!$C$1:$D$323,MATCH(B10,Anterior!$B$2:$B$323,0)+1,2),0)} -> COFEPRIS | L10: =IF(K10=J10,"coinciden",IF(K10=0,"Nuevo","Discrepan")) -> coinciden
A11: {9 | B11: Aristocrat | C11: =IF(ISERROR(LOOKUP(2^15,SEARCH(B11,'2023'!$B$3:$B$1734,1),'2023'!$A$3:$A$1734)),"NO","SI") -> NO | D11: =IF(ISERROR(LOOKUP(2^15,SEARCH(B11,'2022'!$B$2:$B$1591,1),'2022'!$A$2:$A$1591)),"NO","SI") -> NO | E11: =IF(ISERROR(LOOKUP(2^15,SEARCH(B11,'2021'!$B$2:$B$1494,1),'2021'!$A$2:$A$1494)),"NO","SI") -> NO | F11: =IF(ISERROR(LOOKUP(2^15,SEARCH(B11,'2020'!$B$2:$B$1278,1),'2020'!$A$2:$A$1278)),"NO","SI") -> NO | G11: =IF(ISERROR(LOOKUP(2^15,SEARCH(B11,'2019'!$B$2:$B$1108,1),'2019'!$A$2:$A$1108)),"NO","SI") -> NO | H11: =IF(ISERROR(LOOKUP(2^15,SEARCH(B11,'2018'!$B$1:$B$1047,1),'2018'!$A$1:$A$1047)),"NO","SI") -> NO | I11: =IF(ISERROR(LOOKUP(2^15,SEARCH(B11,'ALERTA SANITARIA'!$B$2:$B$269,1),'2018'!$A$1:$A$1047)),"NO","SI") -> SI | J11: =IF(AND(C11="NO", I11="NO"), "Ninguno",IF(AND(C11="NO", I11="SI"), "COFEPRIS",IF(AND(C11="SI",I11="NO"),"DOF","AMBOS"))) -> COFEPRIS | K11: {=IFERROR(INDEX(Anterior!$C$1:$D$323,MATCH(B11,Anterior!$B$2:$B$323,0)+1,2),0)} -> COFEPRIS | L11: =IF(K11=J11,"coinciden",IF(K11=0,"Nuevo","Discrepan")) -> coinciden
A12: {10 | B12: Armada | C12: =IF(ISERROR(LOOKUP(2^15,SEARCH(B12,'2023'!$B$3:$B$1734,1),'2023'!$A$3:$A$1734)),"NO","SI") -> SI | D12: =IF(ISERROR(LOOKUP(2^15,SEARCH(B12,'2022'!$B$2:$B$1591,1),'2022'!$A$2:$A$1591)),"NO","SI") -> SI | E12: =IF(ISERROR(LOOKUP(2^15,SEARCH(B12,'2021'!$B$2:$B$1494,1),'2021'!$A$2:$A$1494)),"NO","SI") -> SI | F12: =IF(ISERROR(LOOKUP(2^15,SEARCH(B12,'2020'!$B$2:$B$1278,1),'2020'!$A$2:$A$1278)),"NO","SI") -> SI | G12: =IF(ISERROR(LOOKUP(2^15,SEARCH(B12,'2019'!$B$2:$B$1108,1),'2019'!$A$2:$A$1108)),"NO","SI") -> SI | H12: =IF(ISERROR(LOOKUP(2^15,SEARCH(B12,'2018'!$B$1:$B$1047,1),'2018'!$A$1:$A$1047)),"NO","SI") -> SI | I12: =IF(ISERROR(LOOKUP(2^15,SEARCH(B12,'ALERTA SANITARIA'!$B$2:$B$269,1),'2018'!$A$1:$A$1047)),"NO","SI") -> SI | J12: =IF(AND(C12="NO", I12="NO"), "Ninguno",IF(AND(C12="NO", I12="SI"), "COFEPRIS",IF(AND(C12="SI",I12="NO"),"DOF","AMBOS"))) -> AMBOS | K12: {=IFERROR(INDEX(Anterior!$C$1:$D$323,MATCH(B12,Anterior!$B$2:$B$323,0)+1,2),0)} -> COFEPRIS | L12: =IF(K12=J12,"coinciden",IF(K12=0,"Nuevo","Discrepan")) -> Discrepan | M12: NO
A13: {11 | B13: Ashford Blue | C13: =IF(ISERROR(LOOKUP(2^15,SEARCH(B13,'2023'!$B$3:$B$1734,1),'2023'!$A$3:$A$1734)),"NO","SI") -> NO | D13: =IF(ISERROR(LOOKUP(2^15,SEARCH(B13,'2022'!$B$2:$B$1591,1),'2022'!$A$2:$A$1591)),"NO","SI") -> NO | E13: =IF(ISERROR(LOOKUP(2^15,SEARCH(B13,'2021'!$B$2:$B$1494,1),'2021'!$A$2:$A$1494)),"NO","SI") -> NO | F13: =IF(ISERROR(LOOKUP(2^15,SEARCH(B13,'2020'!$B$2:$B$1278,1),'2020'!$A$2:$A$1278)),"NO","SI") -> NO | G13: =IF(ISERROR(LOOKUP(2^15,SEARCH(B13,'2019'!$B$2:$B$1108,1),'2019'!$A$2:$A$1108)),"NO","SI") -> NO | H13: =IF(ISERROR(LOOKUP(2^15,SEARCH(B13,'2018'!$B$1:$B$1047,1),'2018'!$A$1:$A$1047)),"NO","SI") -> NO | I13: =IF(ISERROR(LOOKUP(2^15,SEARCH(B13,'ALERTA SANITARIA'!$B$2:$B$269,1),'2018'!$A$1:$A$1047)),"NO","SI") -> SI | J13: =IF(AND(C13="NO", I13="NO"), "Ninguno",IF(AND(C13="NO", I13="SI"), "COFEPRIS",IF(AND(C13="SI",I13="NO"),"DOF","AMBOS"))) -> COFEPRIS | K13: {=IFERROR(INDEX(Anterior!$C$1:$D$323,MATCH(B13,Anterior!$B$2:$B$323,0)+1,2),0)} -> 0 | L13: =IF(K13=J13,"coinciden",IF(K13=0,"Nuevo","Discrepan")) -> Nuevo
A14: {12 | B14: AX Full Flavor | C14: =IF(ISERROR(LOOKUP(2^15,SEARCH(B14,'2023'!$B$3:$B$1734,1),'2023'!$A$3:$A$1734)),"NO","SI") -> NO | D14: =IF(ISERROR(LOOKUP(2^15,SEARCH(B14,'2022'!$B$2:$B$1591,1),'2022'!$A$2:$A$1591)),"NO","SI") -> NO | E14: =IF(ISERROR(LOOKUP(2^15,SEARCH(B14,'2021'!$B$2:$B$1494,1),'2021'!$A$2:$A$1494)),"NO","SI") -> NO | F14: =IF(ISERROR(LOOKUP(2^15,SEARCH(B14,'2020'!$B$2:$B$1278,1),'2020'!$A$2:$A$1278)),"NO","SI") -> NO | G14: =IF(ISERROR(LOOKUP(2^15,SEARCH(B14,'2019'!$B$2:$B$1108,1),'2019'!$A$2:$A$1108)),"NO","SI") -> NO | H14: =IF(ISERROR(LOOKUP(2^15,SEARCH(B14,'2018'!$B$1:$B$1047,1),'2018'!$A$1:$A$1047)),"NO","SI") -> NO | I14: =IF(ISERROR(LOOKUP(2^15,SEARCH(B14,'ALERTA SANITARIA'!$B$2:$B$269,1),'2018'!$A$1:$A$1047)),"NO","SI") -> SI | J14: =IF(AND(C14="NO", I14="NO"), "Ninguno",IF(AND(C14="NO", I14="SI"), "COFEPRIS",IF(AND(C14="SI",I14="NO"),"DOF","AMBOS"))) -> COFEPRIS | K14: {=IFERROR(INDEX(Anterior!$C$1:$D$323,MATCH(B14,Anterior!$B$2:$B$323,0)+1,2),0)} -> COFEPRIS | L14: =IF(K14=J14,"coinciden",IF(K14=0,"Nuevo","Discrepan")) -> coinciden
A15: {13 | B15: B&B (Bulls & Bears) | C15: =IF(ISERROR(LOOKUP(2^15,SEARCH(B15,'2023'!$B$3:$B$1734,1),'2023'!$A$3:$A$1734)),"NO","SI") -> NO | D15: =IF(ISERROR(LOOKUP(2^15,SEARCH(B15,'2022'!$B$2:$B$1591,1),'2022'!$A$2:$A$1591)),"NO","SI") -> NO | E15: =IF(ISERROR(LOOKUP(2^15,SEARCH(B15,'2021'!$B$2:$B$1494,1),'2021'!$A$2:$A$1494)),"NO","SI") -> NO | F15: =IF(ISERROR(LOOKUP(2^15,SEARCH(B15,'2020'!$B$2:$B$1278,1),'2020'!$A$2:$A$1278)),"NO","SI") -> NO | G15: =IF(ISERROR(LOOKUP(2^15,SEARCH(B15,'2019'!$B$2:$B$1108,1),'2019'!$A$2:$A$1108)),"NO","SI") -> NO | H15: =IF(ISERROR(LOOKUP(2^15,SEARCH(B15,'2018'!$B$1:$B$1047,1),'2018'!$A$1:$A$1047)),"NO","SI") -> NO | I15: =IF(ISERROR(LOOKUP(2^15,SEARCH(B15,'ALERTA SANITARIA'!$B$2:$B$269,1),'2018'!$A$1:$A$1047)),"NO","SI") -> SI | J15: =IF(AND(C15="NO", I15="NO"), "Ninguno",IF(AND(C15="NO", I15="SI"), "COFEPRIS",IF(AND(C15="SI",I15="NO"),"DOF","AMBOS"))) -> COFEPRIS | K15: {=IFERROR(INDEX(Anterior!$C$1:$D$323,MATCH(B15,Anterior!$B$2:$B$323,0)+1,2),0)} -> 0 | L15: =IF(K15=J15,"coinciden",IF(K15=0,"Nuevo","Discrepan")) -> Nuevo
A16: {14 | B16: B&J | C16: =IF(ISERROR(LOOKUP(2^15,SEARCH(B16,'2023'!$B$3:$B$1734,1),'2023'!$A$3:$A$1734)),"NO","SI") -> NO | D16: =IF(ISERROR(LOOKUP(2^15,SEARCH(B16,'2022'!$B$2:$B$1591,1),'2022'!$A$2:$A$1591)),"NO","SI") -> NO | E16: =IF(ISERROR(LOOKUP(2^15,SEARCH(B16,'2021'!$B$2:$B$1494,1),'2021'!$A$2:$A$1494)),"NO","SI") -> NO | F16: =IF(ISERROR(LOOKUP(2^15,SEARCH(B16,'2020'!$B$2:$B$1278,1),'2020'!$A$2:$A$1278)),"NO","SI") -> NO | G16: =IF(ISERROR(LOOKUP(2^15,SEARCH(B16,'2019'!$B$2:$B$1108,1),'2019'!$A$2:$A$1108)),"NO","SI") -> NO | H16: =IF(ISERROR(LOOKUP(2^15,SEARCH(B16,'2018'!$B$1:$B$1047,1),'2018'!$A$1:$A$1047)),"NO","SI") -> NO | I16: =IF(ISERROR(LOOKUP(2^15,SEARCH(B16,'ALERTA SANITARIA'!$B$2:$B$269,1),'2018'!$A$1:$A$1047)),"NO","SI") -> SI | J16: =IF(AND(C16="NO", I16="NO"), "Ninguno",IF(AND(C16="NO", I16="SI"), "COFEPRIS",IF(AND(C16="SI",I16="NO"),"DOF","AMBOS"))) -> COFEPRIS | K16: {=IFERROR(INDEX(Anterior!$C$1:$D$323,MATCH(B16,Anterior!$B$2:$B$323,0)+1,2),0)} -> COFEPRIS | L16: =IF(K16=J16,"coinciden",IF(K16=0,"Nuevo","Discrepan")) -> coinciden
A17: {15 | B17: Baronet | C17: =IF(ISERROR(LOOKUP(2^15,SEARCH(B17,'2023'!$B$3:$B$1734,1),'2023'!$A$3:$A$1734)),"NO","SI") -> SI | D17: =IF(ISERROR(LOOKUP(2^15,SEARCH(B17,'2022'!$B$2:$B$1591,1),'2022'!$A$2:$A$1591)),"NO","SI") -> SI | E17: =IF(ISERROR(LOOKUP(2^15,SEARCH(B17,'2021'!$B$2:$B$1494,1),'2021'!$A$2:$A$1494)),"NO","SI") -> SI | F17: =IF(ISERROR(LOOKUP(2^15,SEARCH(B17,'2020'!$B$2:$B$1278,1),'2020'!$A$2:$A$1278)),"NO","SI") -> SI | G17: =IF(ISERROR(LOOKUP(2^15,SEARCH(B17,'2019'!$B$2:$B$1108,1),'2019'!$A$2:$A$1108)),"NO","SI") -> SI | H17: =IF(ISERROR(LOOKUP(2^15,SEARCH(B17,'2018'!$B$1:$B$1047,1),'2018'!$A$1:$A$1047)),"NO","SI") -> SI | I17: =IF(ISERROR(LOOKUP(2^15,SEARCH(B17,'ALERTA SANITARIA'!$B$2:$B$269,1),'2018'!$A$1:$A$1047)),"NO","SI") -> NO | J17: =IF(AND(C17="NO", I17="NO"), "Ninguno",IF(AND(C17="NO", I17="SI"), "COFEPRIS",IF(AND(C17="SI",I17="NO"),"DOF","AMBOS"))) -> DOF | K17: {=IFERROR(INDEX(Anterior!$C$1:$D$323,MATCH(B17,Anterior!$B$2:$B$323,0)+1,2),0)} -> DOF | L17: =IF(K17=J17,"coinciden",IF(K17=0,"Nuevo","Discrepan")) -> coinciden
A18: {16 | B18: Benson & Hedges | C18: =IF(ISERROR(LOOKUP(2^15,SEARCH(B18,'2023'!$B$3:$B$1734,1),'2023'!$A$3:$A$1734)),"NO","SI") -> SI | D18: =IF(ISERROR(LOOKUP(2^15,SEARCH(B18,'2022'!$B$2:$B$1591,1),'2022'!$A$2:$A$1591)),"NO","SI") -> SI | E18: =IF(ISERROR(LOOKUP(2^15,SEARCH(B18,'2021'!$B$2:$B$1494,1),'2021'!$A$2:$A$1494)),"NO","SI") -> SI | F18: =IF(ISERROR(LOOKUP(2^15,SEARCH(B18,'2020'!$B$2:$B$1278,1),'2020'!$A$2:$A$1278)),"NO","SI") -> SI | G18: =IF(ISERROR(LOOKUP(2^15,SEARCH(B18,'2019'!$B$2:$B$1108,1),'2019'!$A$2:$A$1108)),"NO","SI") -> SI | H18: =IF(ISERROR(LOOKUP(2^15,SEARCH(B18,'2018'!$B$1:$B$1047,1),'2018'!$A$1:$A$1047)),"NO","SI") -> SI | I18: =IF(ISERROR(LOOKUP(2^15,SEARCH(B18,'ALERTA SANITARIA'!$B$2:$B$269,1),'2018'!$A$1:$A$1047)),"NO","SI") -> NO | J18: =IF(AND(C18="NO", I18="NO"), "Ninguno",IF(AND(C18="NO", I18="SI"), "COFEPRIS",IF(AND(C18="SI",I18="NO"),"DOF","AMBOS"))) -> DOF | K18: {=IFERROR(INDEX(Anterior!$C$1:$D$323,MATCH(B18,Anterior!$B$2:$B$323,0)+1,2),0)} -> DOF | L18: =IF(K18=J18,"coinciden",IF(K18=0,"Nuevo","Discrepan")) -> coinciden
A19: {17 | B19: Bentley | C19: =IF(ISERROR(LOOKUP(2^15,SEARCH(B19,'2023'!$B$3:$B$1734,1),'2023'!$A$3:$A$1734)),"NO","SI") -> NO | D19: =IF(ISERROR(LOOKUP(2^15,SEARCH(B19,'2022'!$B$2:$B$1591,1),'2022'!$A$2:$A$1591)),"NO","SI") -> NO | E19: =IF(ISERROR(LOOKUP(2^15,SEARCH(B19,'2021'!$B$2:$B$1494,1),'2021'!$A$2:$A$1494)),"NO","SI") -> NO | F19: =IF(ISERROR(LOOKUP(2^15,SEARCH(B19,'2020'!$B$2:$B$1278,1),'2020'!$A$2:$A$1278)),"NO","SI") -> NO | G19: =IF(ISERROR(LOOKUP(2^15,SEARCH(B19,'2019'!$B$2:$B$1108,1),'2019'!$A$2:$A$1108)),"NO","SI") -> NO | H19: =IF(ISERROR(LOOKUP(2^15,SEARCH(B19,'2018'!$B$1:$B$1047,1),'2018'!$A$1:$A$1047)),"NO","SI") -> NO | I19: =IF(ISERROR(LOOKUP(2^15,SEARCH(B19,'ALERTA SANITARIA'!$B$2:$B$269,1),'2018'!$A$1:$A$1047)),"NO","SI") -> SI | J19: =IF(AND(C19="NO", I19="NO"), "Ninguno",IF(AND(C19="NO", I19="SI"), "COFEPRIS",IF(AND(C19="SI",I19="NO"),"DOF","AMBOS"))) -> COFEPRIS | K19: {=IFERROR(INDEX(Anterior!$C$1:$D$323,MATCH(B19,Anterior!$B$2:$B$323,0)+1,2),0)} -> COFEPRIS | L19: =IF(K19=J19,"coinciden",IF(K19=0,"Nuevo","Discrepan")) -> coinciden
A20: {18 | B20: Biasha Nise | C20: =IF(ISERROR(LOOKUP(2^15,SEARCH(B20,'2023'!$B$3:$B$1734,1),'2023'!$A$3:$A$1734)),"NO","SI") -> NO | D20: =IF(ISERROR(LOOKUP(2^15,SEARCH(B20,'2022'!$B$2:$B$1591,1),'2022'!$A$2:$A$1591)),"NO","SI") -> NO | E20: =IF(ISERROR(LOOKUP(2^15,SEARCH(B20,'2021'!$B$2:$B$1494,1),'2021'!$A$2:$A$1494)),"NO","SI") -> NO | F20: =IF(ISERROR(LOOKUP(2^15,SEARCH(B20,'2020'!$B$2:$B$1278,1),'2020'!$A$2:$A$1278)),"NO","SI") -> NO | G20: =IF(ISERROR(LOOKUP(2^15,SEARCH(B20,'2019'!$B$2:$B$1108,1),'2019'!$A$2:$A$1108)),"NO","SI") -> NO | H20: =IF(ISERROR(LOOKUP(2^15,SEARCH(B20,'2018'!$B$1:$B$1047,1),'2018'!$A$1:$A$1047)),"NO","SI") -> NO | I20: =IF(ISERROR(LOOKUP(2^15,SEARCH(B20,'ALERTA SANITARIA'!$B$2:$B$269,1),'2018'!$A$1:$A$1047)),"NO","SI") -> SI | J20: =IF(AND(C20="NO", I20="NO"), "Ninguno",IF(AND(C20="NO", I20="SI"), "COFEPRIS",IF(AND(C20="SI",I20="NO"),"DOF","AMBOS"))) -> COFEPRIS | K20: {=IFERROR(INDEX(Anterior!$C$1:$D$323,MATCH(B20,Anterior!$B$2:$B$323,0)+1,2),0)} -> COFEPRIS | L20: =IF(K20=J20,"coinciden",IF(K20=0,"Nuevo","Discrepan")) -> coinciden
A21: {19 | B21: Big Chief | C21: =IF(ISERROR(LOOKUP(2^15,SEARCH(B21,'2023'!$B$3:$B$1734,1),'2023'!$A$3:$A$1734)),"NO","SI") -> NO | D21: =IF(ISERROR(LOOKUP(2^15,SEARCH(B21,'2022'!$B$2:$B$1591,1),'2022'!$A$2:$A$1591)),"NO","SI") -> NO | E21: =IF(ISERROR(LOOKUP(2^15,SEARCH(B21,'2021'!$B$2:$B$1494,1),'2021'!$A$2:$A$1494)),"NO","SI") -> NO | F21: =IF(ISERROR(LOOKUP(2^15,SEARCH(B21,'2020'!$B$2:$B$1278,1),'2020'!$A$2:$A$1278)),"NO","SI") -> NO | G21: =IF(ISERROR(LOOKUP(2^15,SEARCH(B21,'2019'!$B$2:$B$1108,1),'2019'!$A$2:$A$1108)),"NO","SI") -> NO | H21: =IF(ISERROR(LOOKUP(2^15,SEARCH(B21,'2018'!$B$1:$B$1047,1),'2018'!$A$1:$A$1047)),"NO","SI") -> NO | I21: =IF(ISERROR(LOOKUP(2^15,SEARCH(B21,'ALERTA SANITARIA'!$B$2:$B$269,1),'2018'!$A$1:$A$1047)),"NO","SI") -> SI | J21: =IF(AND(C21="NO", I21="NO"), "Ninguno",IF(AND(C21="NO", I21="SI"), "COFEPRIS",IF(AND(C21="SI",I21="NO"),"DOF","AMBOS"))) -> COFEPRIS | K21: {=IFERROR(INDEX(Anterior!$C$1:$D$323,MATCH(B21,Anterior!$B$2:$B$323,0)+1,2),0)} -> COFEPRIS | L21: =IF(K21=J21,"coinciden",IF(K21=0,"Nuevo","Discrepan")) -> coinciden
A22: {20 | B22: Birmingham | C22: =IF(ISERROR(LOOKUP(2^15,SEARCH(B22,'2023'!$B$3:$B$1734,1),'2023'!$A$3:$A$1734)),"NO","SI") -> NO | D22: =IF(ISERROR(LOOKUP(2^15,SEARCH(B22,'2022'!$B$2:$B$1591,1),'2022'!$A$2:$A$1591)),"NO","SI") -> NO | E22: =IF(ISERROR(LOOKUP(2^15,SEARCH(B22,'2021'!$B$2:$B$1494,1),'2021'!$A$2:$A$1494)),"NO","SI") -> NO | F22: =IF(ISERROR(LOOKUP(2^15,SEARCH(B22,'2020'!$B$2:$B$1278,1),'2020'!$A$2:$A$1278)),"NO","SI") -> NO | G22: =IF(ISERROR(LOOKUP(2^15,SEARCH(B22,'2019'!$B$2:$B$1108,1),'2019'!$A$2:$A$1108)),"NO","SI") -> NO | H22: =IF(ISERROR(LOOKUP(2^15,SEARCH(B22,'2018'!$B$1:$B$1047,1),'2018'!$A$1:$A$1047)),"NO","SI") -> NO | I22: =IF(ISERROR(LOOKUP(2^15,SEARCH(B22,'ALERTA SANITARIA'!$B$2:$B$269,1),'2018'!$A$1:$A$1047)),"NO","SI") -> SI | J22: =IF(AND(C22="NO", I22="NO"), "Ninguno",IF(AND(C22="NO", I22="SI"), "COFEPRIS",IF(AND(C22="SI",I22="NO"),"DOF","AMBOS"))) -> COFEPRIS | K22: {=IFERROR(INDEX(Anterior!$C$1:$D$323,MATCH(B22,Anterior!$B$2:$B$323,0)+1,2),0)} -> COFEPRIS | L22: =IF(K22=J22,"coinciden",IF(K22=0,"Nuevo","Discrepan")) -> coinciden
A23: {21 | B23: Black and White | C23: =IF(ISERROR(LOOKUP(2^15,SEARCH(B23,'2023'!$B$3:$B$1734,1),'2023'!$A$3:$A$1734)),"NO","SI") -> NO | D23: =IF(ISERROR(LOOKUP(2^15,SEARCH(B23,'2022'!$B$2:$B$1591,1),'2022'!$A$2:$A$1591)),"NO","SI") -> NO | E23: =IF(ISERROR(LOOKUP(2^15,SEARCH(B23,'2021'!$B$2:$B$1494,1),'2021'!$A$2:$A$1494)),"NO","SI") -> NO | F23: =IF(ISERROR(LOOKUP(2^15,SEARCH(B23,'2020'!$B$2:$B$1278,1),'2020'!$A$2:$A$1278)),"NO","SI") -> NO | G23: =IF(ISERROR(LOOKUP(2^15,SEARCH(B23,'2019'!$B$2:$B$1108,1),'2019'!$A$2:$A$1108)),"NO","SI") -> NO | H23: =IF(ISERROR(LOOKUP(2^15,SEARCH(B23,'2018'!$B$1:$B$1047,1),'2018'!$A$1:$A$1047)),"NO","SI") -> NO | I23: =IF(ISERROR(LOOKUP(2^15,SEARCH(B23,'ALERTA SANITARIA'!$B$2:$B$269,1),'2018'!$A$1:$A$1047)),"NO","SI") -> SI | J23: =IF(AND(C23="NO", I23="NO"), "Ninguno",IF(AND(C23="NO", I23="SI"), "COFEPRIS",IF(AND(C23="SI",I23="NO"),"DOF","AMBOS"))) -> COFEPRIS | K23: {=IFERROR(INDEX(Anterior!$C$1:$D$323,MATCH(B23,Anterior!$B$2:$B$323,0)+1,2),0)} -> COFEPRIS | L23: =IF(K23=J23,"coinciden",IF(K23=0,"Nuevo","Discrepan")) -> coinciden
A24: {22 | B24: Black Horse Stallion | C24: =IF(ISERROR(LOOKUP(2^15,SEARCH(B24,'2023'!$B$3:$B$1734,1),'2023'!$A$3:$A$1734)),"NO","SI") -> NO | D24: =IF(ISERROR(LOOKUP(2^15,SEARCH(B24,'2022'!$B$2:$B$1591,1),'2022'!$A$2:$A$1591)),"NO","SI") -> NO | E24: =IF(ISERROR(LOOKUP(2^15,SEARCH(B24,'2021'!$B$2:$B$1494,1),'2021'!$A$2:$A$1494)),"NO","SI") -> NO | F24: =IF(ISERROR(LOOKUP(2^15,SEARCH(B24,'2020'!$B$2:$B$1278,1),'2020'!$A$2:$A$1278)),"NO","SI") -> NO | G24: =IF(ISERROR(LOOKUP(2^15,SEARCH(B24,'2019'!$B$2:$B$1108,1),'2019'!$A$2:$A$1108)),"NO","SI") -> NO | H24: =IF(ISERROR(LOOKUP(2^15,SEARCH(B24,'2018'!$B$1:$B$1047,1),'2018'!$A$1:$A$1047)),"NO","SI") -> NO | I24: =IF(ISERROR(LOOKUP(2^15,SEARCH(B24,'ALERTA SANITARIA'!$B$2:$B$269,1),'2018'!$A$1:$A$1047)),"NO","SI") -> SI | J24: =IF(AND(C24="NO", I24="NO"), "Ninguno",IF(AND(C24="NO", I24="SI"), "COFEPRIS",IF(AND(C24="SI",I24="NO"),"DOF","AMBOS"))) -> COFEPRIS | K24: {=IFERROR(INDEX(Anterior!$C$1:$D$323,MATCH(B24,Anterior!$B$2:$B$323,0)+1,2),0)} -> COFEPRIS | L24: =IF(K24=J24,"coinciden",IF(K24=0,"Nuevo","Discrepan")) -> coinciden
A25: {23 | B25: Black Jack | C25: =IF(ISERROR(LOOKUP(2^15,SEARCH(B25,'2023'!$B$3:$B$1734,1),'2023'!$A$3:$A$1734)),"NO","SI") -> SI | D25: =IF(ISERROR(LOOKUP(2^15,SEARCH(B25,'2022'!$B$2:$B$1591,1),'2022'!$A$2:$A$1591)),"NO","SI") -> SI | E25: =IF(ISERROR(LOOKUP(2^15,SEARCH(B25,'2021'!$B$2:$B$1494,1),'2021'!$A$2:$A$1494)),"NO","SI") -> SI | F25: =IF(ISERROR(LOOKUP(2^15,SEARCH(B25,'2020'!$B$2:$B$1278,1),'2020'!$A$2:$A$1278)),"NO","SI") -> SI | G25: =IF(ISERROR(LOOKUP(2^15,SEARCH(B25,'2019'!$B$2:$B$1108,1),'2019'!$A$2:$A$1108)),"NO","SI") -> SI | H25: =IF(ISERROR(LOOKUP(2^15,SEARCH(B25,'2018'!$B$1:$B$1047,1),'2018'!$A$1:$A$1047)),"NO","SI") -> SI | I25: =IF(ISERROR(LOOKUP(2^15,SEARCH(B25,'ALERTA SANITARIA'!$B$2:$B$269,1),'2018'!$A$1:$A$1047)),"NO","SI") -> SI | J25: =IF(AND(C25="NO", I25="NO"), "Ninguno",IF(AND(C25="NO", I25="SI"), "COFEPRIS",IF(AND(C25="SI",I25="NO"),"DOF","AMBOS"))) -> AMBOS | K25: {=IFERROR(INDEX(Anterior!$C$1:$D$323,MATCH(B25,Anterior!$B$2:$B$323,0)+1,2),0)} -> Ambos | L25: =IF(K25=J25,"coinciden",IF(K25=0,"Nuevo","Discrepan")) -> coinciden | M25: NO
A26: {24 | B26: Blend Type Box | C26: =IF(ISERROR(LOOKUP(2^15,SEARCH(B26,'2023'!$B$3:$B$1734,1),'2023'!$A$3:$A$1734)),"NO","SI") -> NO | D26: =IF(ISERROR(LOOKUP(2^15,SEARCH(B26,'2022'!$B$2:$B$1591,1),'2022'!$A$2:$A$1591)),"NO","SI") -> NO | E26: =IF(ISERROR(LOOKUP(2^15,SEARCH(B26,'2021'!$B$2:$B$1494,1),'2021'!$A$2:$A$1494)),"NO","SI") -> NO | F26: =IF(ISERROR(LOOKUP(2^15,SEARCH(B26,'2020'!$B$2:$B$1278,1),'2020'!$A$2:$A$1278)),"NO","SI") -> NO | G26: =IF(ISERROR(LOOKUP(2^15,SEARCH(B26,'2019'!$B$2:$B$1108,1),'2019'!$A$2:$A$1108)),"NO","SI") -> NO | H26: =IF(ISERROR(LOOKUP(2^15,SEARCH(B26,'2018'!$B$1:$B$1047,1),'2018'!$A$1:$A$1047)),"NO","SI") -> NO | I26: =IF(ISERROR(LOOKUP(2^15,SEARCH(B26,'ALERTA SANITARIA'!$B$2:$B$269,1),'2018'!$A$1:$A$1047)),"NO","SI") -> SI | J26: =IF(AND(C26="NO", I26="NO"), "Ninguno",IF(AND(C26="NO", I26="SI"), "COFEPRIS",IF(AND(C26="SI",I26="NO"),"DOF","AMBOS"))) -> COFEPRIS | K26: {=IFERROR(INDEX(Anterior!$C$1:$D$323,MATCH(B26,Anterior!$B$2:$B$323,0)+1,2),0)} -> COFEPRIS | L26: =IF(K26=J26,"coinciden",IF(K26=0,"Nuevo","Discrepan")) -> coinciden
A27: {25 | B27: Blitz | C27: =IF(ISERROR(LOOKUP(2^15,SEARCH(B27,'2023'!$B$3:$B$1734,1),'2023'!$A$3:$A$1734)),"NO","SI") -> NO | D27: =IF(ISERROR(LOOKUP(2^15,SEARCH(B27,'2022'!$B$2:$B$1591,1),'2022'!$A$2:$A$1591)),"NO","SI") -> NO | E27: =IF(ISERROR(LOOKUP(2^15,SEARCH(B27,'2021'!$B$2:$B$1494,1),'2021'!$A$2:$A$1494)),"NO","SI") -> NO | F27: =IF(ISERROR(LOOKUP(2^15,SEARCH(B27,'2020'!$B$2:$B$1278,1),'2020'!$A$2:$A$1278)),"NO","SI") -> NO | G27: =IF(ISERROR(LOOKUP(2^15,SEARCH(B27,'2019'!$B$2:$B$1108,1),'2019'!$A$2:$A$1108)),"NO","SI") -> NO | H27: =IF(ISERROR(LOOKUP(2^15,SEARCH(B27,'2018'!$B$1:$B$1047,1),'2018'!$A$1:$A$1047)),"NO","SI") -> NO | I27: =IF(ISERROR(LOOKUP(2^15,SEARCH(B27,'ALERTA SANITARIA'!$B$2:$B$269,1),'2018'!$A$1:$A$1047)),"NO","SI") -> SI | J27: =IF(AND(C27="NO", I27="NO"), "Ninguno",IF(AND(C27="NO", I27="SI"), "COFEPRIS",IF(AND(C27="SI",I27="NO"),"DOF","AMBOS"))) -> COFEPRIS | K27: {=IFERROR(INDEX(Anterior!$C$1:$D$323,MATCH(B27,Anterior!$B$2:$B$323,0)+1,2),0)} -> COFEPRIS | L27: =IF(K27=J27,"coinciden",IF(K27=0,"Nuevo","Discrepan")) -> coinciden
A28: {26 | B28: Blue River | C28: =IF(ISERROR(LOOKUP(2^15,SEARCH(B28,'2023'!$B$3:$B$1734,1),'2023'!$A$3:$A$1734)),"NO","SI") -> NO | D28: =IF(ISERROR(LOOKUP(2^15,SEARCH(B28,'2022'!$B$2:$B$1591,1),'2022'!$A$2:$A$1591)),"NO","SI") -> NO | E28: =IF(ISERROR(LOOKUP(2^15,SEARCH(B28,'2021'!$B$2:$B$1494,1),'2021'!$A$2:$A$1494)),"NO","SI") -> NO | F28: =IF(ISERROR(LOOKUP(2^15,SEARCH(B28,'2020'!$B$2:$B$1278,1),'2020'!$A$2:$A$1278)),"NO","SI") -> NO | G28: =IF(ISERROR(LOOKUP(2^15,SEARCH(B28,'2019'!$B$2:$B$1108,1),'2019'!$A$2:$A$1108)),"NO","SI") -> NO | H28: =IF(ISERROR(LOOKUP(2^15,SEARCH(B28,'2018'!$B$1:$B$1047,1),'2018'!$A$1:$A$1047)),"NO","SI") -> NO | I28: =IF(ISERROR(LOOKUP(2^15,SEARCH(B28,'ALERTA SANITARIA'!$B$2:$B$269,1),'2018'!$A$1:$A$1047)),"NO","SI") -> SI | J28: =IF(AND(C28="NO", I28="NO"), "Ninguno",IF(AND(C28="NO", I28="SI"), "COFEPRIS",IF(AND(C28="SI",I28="NO"),"DOF","AMBOS"))) -> COFEPRIS | K28: {=IFERROR(INDEX(Anterior!$C$1:$D$323,MATCH(B28,Anterior!$B$2:$B$323,0)+1,2),0)} -> COFEPRIS | L28: =IF(K28=J28,"coinciden",IF(K28=0,"Nuevo","Discrepan")) -> coinciden
A29: {27 | B29: Boaz | C29: =IF(ISERROR(LOOKUP(2^15,SEARCH(B29,'2023'!$B$3:$B$1734,1),'2023'!$A$3:$A$1734)),"NO","SI") -> NO | D29: =IF(ISERROR(LOOKUP(2^15,SEARCH(B29,'2022'!$B$2:$B$1591,1),'2022'!$A$2:$A$1591)),"NO","SI") -> NO | E29: =IF(ISERROR(LOOKUP(2^15,SEARCH(B29,'2021'!$B$2:$B$1494,1),'2021'!$A$2:$A$1494)),"NO","SI") -> NO | F29: =IF(ISERROR(LOOKUP(2^15,SEARCH(B29,'2020'!$B$2:$B$1278,1),'2020'!$A$2:$A$1278)),"NO","SI") -> NO | G29: =IF(ISERROR(LOOKUP(2^15,SEARCH(B29,'2019'!$B$2:$B$1108,1),'2019'!$A$2:$A$1108)),"NO","SI") -> NO | H29: =IF(ISERROR(LOOKUP(2^15,SEARCH(B29,'2018'!$B$1:$B$1047,1),'2018'!$A$1:$A$1047)),"NO","SI") -> NO | I29: =IF(ISERROR(LOOKUP(2^15,SEARCH(B29,'ALERTA SANITARIA'!$B$2:$B$269,1),'2018'!$A$1:$A$1047)),"NO","SI") -> SI | J29: =IF(AND(C29="NO", I29="NO"), "Ninguno",IF(AND(C29="NO", I29="SI"), "COFEPRIS",IF(AND(C29="SI",I29="NO"),"DOF","AMBOS"))) -> COFEPRIS | K29: {=IFERROR(INDEX(Anterior!$C$1:$D$323,MATCH(B29,Anterior!$B$2:$B$323,0)+1,2),0)} -> COFEPRIS | L29: =IF(K29=J29,"coinciden",IF(K29=0,"Nuevo","Discrepan")) -> coinciden
A30: {28 | B30: Bohemios | C30: =IF(ISERROR(LOOKUP(2^15,SEARCH(B30,'2023'!$B$3:$B$1734,1),'2023'!$A$3:$A$1734)),"NO","SI") -> SI | D30: =IF(ISERROR(LOOKUP(2^15,SEARCH(B30,'2022'!$B$2:$B$1591,1),'2022'!$A$2:$A$1591)),"NO","SI") -> SI | E30: =IF(ISERROR(LOOKUP(2^15,SEARCH(B30,'2021'!$B$2:$B$1494,1),'2021'!$A$2:$A$1494)),"NO","SI") -> SI | F30: =IF(ISERROR(LOOKUP(2^15,SEARCH(B30,'2020'!$B$2:$B$1278,1),'2020'!$A$2:$A$1278)),"NO","SI") -> SI | G30: =IF(ISERROR(LOOKUP(2^15,SEARCH(B30,'2019'!$B$2:$B$1108,1),'2019'!$A$2:$A$1108)),"NO","SI") -> SI | H30: =IF(ISERROR(LOOKUP(2^15,SEARCH(B30,'2018'!$B$1:$B$1047,1),'2018'!$A$1:$A$1047)),"NO","SI") -> SI | I30: =IF(ISERROR(LOOKUP(2^15,SEARCH(B30,'ALERTA SANITARIA'!$B$2:$B$269,1),'2018'!$A$1:$A$1047)),"NO","SI") -> NO | J30: =IF(AND(C30="NO", I30="NO"), "Ninguno",IF(AND(C30="NO", I30="SI"), "COFEPRIS",IF(AND(C30="SI",I30="NO"),"DOF","AMBOS"))) -> DOF | K30: {=IFERROR(INDEX(Anterior!$C$1:$D$323,MATCH(B30,Anterior!$B$2:$B$323,0)+1,2),0)} -> DOF | L30: =IF(K30=J30,"coinciden",IF(K30=0,"Nuevo","Discrepan")) -> coinciden
A31: {29 | B31: Boots | C31: =IF(ISERROR(LOOKUP(2^15,SEARCH(B31,'2023'!$B$3:$B$1734,1),'2023'!$A$3:$A$1734)),"NO","SI") -> SI | D31: =IF(ISERROR(LOOKUP(2^15,SEARCH(B31,'2022'!$B$2:$B$1591,1),'2022'!$A$2:$A$1591)),"NO","SI") -> SI | E31: =IF(ISERROR(LOOKUP(2^15,SEARCH(B31,'2021'!$B$2:$B$1494,1),'2021'!$A$2:$A$1494)),"NO","SI") -> SI | F31: =IF(ISERROR(LOOKUP(2^15,SEARCH(B31,'2020'!$B$2:$B$1278,1),'2020'!$A$2:$A$1278)),"NO","SI") -> SI | G31: =IF(ISERROR(LOOKUP(2^15,SEARCH(B31,'2019'!$B$2:$B$1108,1),'2019'!$A$2:$A$1108)),"NO","SI") -> SI | H31: =IF(ISERROR(LOOKUP(2^15,SEARCH(B31,'2018'!$B$1:$B$1047,1),'2018'!$A$1:$A$1047)),"NO","SI") -> SI | I31: =IF(ISERROR(LOOKUP(2^15,SEARCH(B31,'ALERTA SANITARIA'!$B$2:$B$269,1),'2018'!$A$1:$A$1047)),"NO","SI") -> SI | J31: =IF(AND(C31="NO", I31="NO"), "Ninguno",IF(AND(C31="NO", I31="SI"), "COFEPRIS",IF(AND(C31="SI",I31="NO"),"DOF","AMBOS"))) -> AMBOS | K31: {=IFERROR(INDEX(Anterior!$C$1:$D$323,MATCH(B31,Anterior!$B$2:$B$323,0)+1,2),0)} -> DOF | L31: =IF(K31=J31,"coinciden",IF(K31=0,"Nuevo","Discrepan")) -> Discrepan | M31: NO
A32: {30 | B32: Botas | C32: =IF(ISERROR(LOOKUP(2^15,SEARCH(B32,'2023'!$B$3:$B$1734,1),'2023'!$A$3:$A$1734)),"NO","SI") -> SI | D32: =IF(ISERROR(LOOKUP(2^15,SEARCH(B32,'2022'!$B$2:$B$1591,1),'2022'!$A$2:$A$1591)),"NO","SI") -> SI | E32: =IF(ISERROR(LOOKUP(2^15,SEARCH(B32,'2021'!$B$2:$B$1494,1),'2021'!$A$2:$A$1494)),"NO","SI") -> SI | F32: =IF(ISERROR(LOOKUP(2^15,SEARCH(B32,'2020'!$B$2:$B$1278,1),'2020'!$A$2:$A$1278)),"NO","SI") -> SI | G32: =IF(ISERROR(LOOKUP(2^15,SEARCH(B32,'2019'!$B$2:$B$1108,1),'2019'!$A$2:$A$1108)),"NO","SI") -> SI | H32: =IF(ISERROR(LOOKUP(2^15,SEARCH(B32,'2018'!$B$1:$B$1047,1),'2018'!$A$1:$A$1047)),"NO","SI") -> SI | I32: =IF(ISERROR(LOOKUP(2^15,SEARCH(B32,'ALERTA SANITARIA'!$B$2:$B$269,1),'2018'!$A$1:$A$1047)),"NO","SI") -> NO | J32: =IF(AND(C32="NO", I32="NO"), "Ninguno",IF(AND(C32="NO", I32="SI"), "COFEPRIS",IF(AND(C32="SI",I32="NO"),"DOF","AMBOS"))) -> DOF | K32: {=IFERROR(INDEX(Anterior!$C$1:$D$323,MATCH(B32,Anterior!$B$2:$B$323,0)+1,2),0)} -> DOF | L32: =IF(K32=J32,"coinciden",IF(K32=0,"Nuevo","Discrepan")) -> coinciden
A33: {31 | B33: Brass | C33: =IF(ISERROR(LOOKUP(2^15,SEARCH(B33,'2023'!$B$3:$B$1734,1),'2023'!$A$3:$A$1734)),"NO","SI") -> NO | D33: =IF(ISERROR(LOOKUP(2^15,SEARCH(B33,'2022'!$B$2:$B$1591,1),'2022'!$A$2:$A$1591)),"NO","SI") -> NO | E33: =IF(ISERROR(LOOKUP(2^15,SEARCH(B33,'2021'!$B$2:$B$1494,1),'2021'!$A$2:$A$1494)),"NO","SI") -> NO | F33: =IF(ISERROR(LOOKUP(2^15,SEARCH(B33,'2020'!$B$2:$B$1278,1),'2020'!$A$2:$A$1278)),"NO","SI") -> NO | G33: =IF(ISERROR(LOOKUP(2^15,SEARCH(B33,'2019'!$B$2:$B$1108,1),'2019'!$A$2:$A$1108)),"NO","SI") -> NO | H33: =IF(ISERROR(LOOKUP(2^15,SEARCH(B33,'2018'!$B$1:$B$1047,1),'2018'!$A$1:$A$1047)),"NO","SI") -> NO | I33: =IF(ISERROR(LOOKUP(2^15,SEARCH(B33,'ALERTA SANITARIA'!$B$2:$B$269,1),'2018'!$A$1:$A$1047)),"NO","SI") -> SI | J33: =IF(AND(C33="NO", I33="NO"), "Ninguno",IF(AND(C33="NO", I33="SI"), "COFEPRIS",IF(AND(C33="SI",I33="NO"),"DOF","AMBOS"))) -> COFEPRIS | K33: {=IFERROR(INDEX(Anterior!$C$1:$D$323,MATCH(B33,Anterior!$B$2:$B$323,0)+1,2),0)} -> COFEPRIS | L33: =IF(K33=J33,"coinciden",IF(K33=0,"Nuevo","Discrepan")) -> coinciden
A34: {32 | B34: Bright | C34: =IF(ISERROR(LOOKUP(2^15,SEARCH(B34,'2023'!$B$3:$B$1734,1),'2023'!$A$3:$A$1734)),"NO","SI") -> NO | D34: =IF(ISERROR(LOOKUP(2^15,SEARCH(B34,'2022'!$B$2:$B$1591,1),'2022'!$A$2:$A$1591)),"NO","SI") -> NO | E34: =IF(ISERROR(LOOKUP(2^15,SEARCH(B34,'2021'!$B$2:$B$1494,1),'2021'!$A$2:$A$1494)),"NO","SI") -> NO | F34: =IF(ISERROR(LOOKUP(2^15,SEARCH(B34,'2020'!$B$2:$B$1278,1),'2020'!$A$2:$A$1278)),"NO","SI") -> NO | G34: =IF(ISERROR(LOOKUP(2^15,SEARCH(B34,'2019'!$B$2:$B$1108,1),'2019'!$A$2:$A$1108)),"NO","SI") -> NO | H34: =IF(ISERROR(LOOKUP(2^15,SEARCH(B34,'2018'!$B$1:$B$1047,1),'2018'!$A$1:$A$1047)),"NO","SI") -> NO | I34: =IF(ISERROR(LOOKUP(2^15,SEARCH(B34,'ALERTA SANITARIA'!$B$2:$B$269,1),'2018'!$A$1:$A$1047)),"NO","SI") -> SI | J34: =IF(AND(C34="NO", I34="NO"), "Ninguno",IF(AND(C34="NO", I34="SI"), "COFEPRIS",IF(AND(C34="SI",I34="NO"),"DOF","AMBOS"))) -> COFEPRIS | K34: {=IFERROR(INDEX(Anterior!$C$1:$D$323,MATCH(B34,Anterior!$B$2:$B$323,0)+1,2),0)} -> COFEPRIS | L34: =IF(K34=J34,"coinciden",IF(K34=0,"Nuevo","Discrepan")) -> coinciden
A35: {33 | B35: Bronco | C35: =IF(ISERROR(LOOKUP(2^15,SEARCH(B35,'2023'!$B$3:$B$1734,1),'2023'!$A$3:$A$1734)),"NO","SI") -> NO | D35: =IF(ISERROR(LOOKUP(2^15,SEARCH(B35,'2022'!$B$2:$B$1591,1),'2022'!$A$2:$A$1591)),"NO","SI") -> NO | E35: =IF(ISERROR(LOOKUP(2^15,SEARCH(B35,'2021'!$B$2:$B$1494,1),'2021'!$A$2:$A$1494)),"NO","SI") -> NO | F35: =IF(ISERROR(LOOKUP(2^15,SEARCH(B35,'2020'!$B$2:$B$1278,1),'2020'!$A$2:$A$1278)),"NO","SI") -> NO | G35: =IF(ISERROR(LOOKUP(2^15,SEARCH(B35,'2019'!$B$2:$B$1108,1),'2019'!$A$2:$A$1108)),"NO","SI") -> NO | H35: =IF(ISERROR(LOOKUP(2^15,SEARCH(B35,'2018'!$B$1:$B$1047,1),'2018'!$A$1:$A$1047)),"NO","SI") -> NO | I35: =IF(ISERROR(LOOKUP(2^15,SEARCH(B35,'ALERTA SANITARIA'!$B$2:$B$269,1),'2018'!$A$1:$A$1047)),"NO","SI") -> SI | J35: =IF(AND(C35="NO", I35="NO"), "Ninguno",IF(AND(C35="NO", I35="SI"), "COFEPRIS",IF(AND(C35="SI",I35="NO"),"DOF","AMBOS"))) -> COFEPRIS | K35: {=IFERROR(INDEX(Anterior!$C$1:$D$323,MATCH(B35,Anterior!$B$2:$B$323,0)+1,2),0)} -> COFEPRIS | L35: =IF(K35=J35,"coinciden",IF(K35=0,"Nuevo","Discrepan")) -> coinciden
A36: {34 | B36: Buffalo | C36: =IF(ISERROR(LOOKUP(2^15,SEARCH(B36,'2023'!$B$3:$B$1734,1),'2023'!$A$3:$A$1734)),"NO","SI") -> NO | D36: =IF(ISERROR(LOOKUP(2^15,SEARCH(B36,'2022'!$B$2:$B$1591,1),'2022'!$A$2:$A$1591)),"NO","SI") -> NO | E36: =IF(ISERROR(LOOKUP(2^15,SEARCH(B36,'2021'!$B$2:$B$1494,1),'2021'!$A$2:$A$1494)),"NO","SI") -> NO | F36: =IF(ISERROR(LOOKUP(2^15,SEARCH(B36,'2020'!$B$2:$B$1278,1),'2020'!$A$2:$A$1278)),"NO","SI") -> NO | G36: =IF(ISERROR(LOOKUP(2^15,SEARCH(B36,'2019'!$B$2:$B$1108,1),'2019'!$A$2:$A$1108)),"NO","SI") -> NO | H36: =IF(ISERROR(LOOKUP(2^15,SEARCH(B36,'2018'!$B$1:$B$1047,1),'2018'!$A$1:$A$1047)),"NO","SI") -> NO | I36: =IF(ISERROR(LOOKUP(2^15,SEARCH(B36,'ALERTA SANITARIA'!$B$2:$B$269,1),'2018'!$A$1:$A$1047)),"NO","SI") -> SI | J36: =IF(AND(C36="NO", I36="NO"), "Ninguno",IF(AND(C36="NO", I36="SI"), "COFEPRIS",IF(AND(C36="SI",I36="NO"),"DOF","AMBOS"))) -> COFEPRIS | K36: {=IFERROR(INDEX(Anterior!$C$1:$D$323,MATCH(B36,Anterior!$B$2:$B$323,0)+1,2),0)} -> COFEPRIS | L36: =IF(K36=J36,"coinciden",IF(K36=0,"Nuevo","Discrepan")) -> coinciden
A37: {35 | B37: Bull's eye | C37: =IF(ISERROR(LOOKUP(2^15,SEARCH(B37,'2023'!$B$3:$B$1734,1),'2023'!$A$3:$A$1734)),"NO","SI") -> NO | D37: =IF(ISERROR(LOOKUP(2^15,SEARCH(B37,'2022'!$B$2:$B$1591,1),'2022'!$A$2:$A$1591)),"NO","SI") -> NO | E37: =IF(ISERROR(LOOKUP(2^15,SEARCH(B37,'2021'!$B$2:$B$1494,1),'2021'!$A$2:$A$1494)),"NO","SI") -> NO | F37: =IF(ISERROR(LOOKUP(2^15,SEARCH(B37,'2020'!$B$2:$B$1278,1),'2020'!$A$2:$A$1278)),"NO","SI") -> NO | G37: =IF(ISERROR(LOOKUP(2^15,SEARCH(B37,'2019'!$B$2:$B$1108,1),'2019'!$A$2:$A$1108)),"NO","SI") -> NO | H37: =IF(ISERROR(LOOKUP(2^15,SEARCH(B37,'2018'!$B$1:$B$1047,1),'2018'!$A$1:$A$1047)),"NO","SI") -> NO | I37: =IF(ISERROR(LOOKUP(2^15,SEARCH(B37,'ALERTA SANITARIA'!$B$2:$B$269,1),'2018'!$A$1:$A$1047)),"NO","SI") -> SI | J37: =IF(AND(C37="NO", I37="NO"), "Ninguno",IF(AND(C37="NO", I37="SI"), "COFEPRIS",IF(AND(C37="SI",I37="NO"),"DOF","AMBOS"))) -> COFEPRIS | K37: {=IFERROR(INDEX(Anterior!$C$1:$D$323,MATCH(B37,Anterior!$B$2:$B$323,0)+1,2),0)} -> 0 | L37: =IF(K37=J37,"coinciden",IF(K37=0,"Nuevo","Discrepan")) -> Nuevo
A38: {36 | B38: Bulls | C38: =IF(ISERROR(LOOKUP(2^15,SEARCH(B38,'2023'!$B$3:$B$1734,1),'2023'!$A$3:$A$1734)),"NO","SI") -> NO | D38: =IF(ISERROR(LOOKUP(2^15,SEARCH(B38,'2022'!$B$2:$B$1591,1),'2022'!$A$2:$A$1591)),"NO","SI") -> NO | E38: =IF(ISERROR(LOOKUP(2^15,SEARCH(B38,'2021'!$B$2:$B$1494,1),'2021'!$A$2:$A$1494)),"NO","SI") -> NO | F38: =IF(ISERROR(LOOKUP(2^15,SEARCH(B38,'2020'!$B$2:$B$1278,1),'2020'!$A$2:$A$1278)),"NO","SI") -> NO | G38: =IF(ISERROR(LOOKUP(2^15,SEARCH(B38,'2019'!$B$2:$B$1108,1),'2019'!$A$2:$A$1108)),"NO","SI") -> NO | H38: =IF(ISERROR(LOOKUP(2^15,SEARCH(B38,'2018'!$B$1:$B$1047,1),'2018'!$A$1:$A$1047)),"NO","SI") -> NO | I38: =IF(ISERROR(LOOKUP(2^15,SEARCH(B38,'ALERTA SANITARIA'!$B$2:$B$269,1),'2018'!$A$1:$A$1047)),"NO","SI") -> SI | J38: =IF(AND(C38="NO", I38="NO"), "Ninguno",IF(AND(C38="NO", I38="SI"), "COFEPRIS",IF(AND(C38="SI",I38="NO"),"DOF","AMBOS"))) -> COFEPRIS | K38: {=IFERROR(INDEX(Anterior!$C$1:$D$323,MATCH(B38,Anterior!$B$2:$B$323,0)+1,2),0)} -> COFEPRIS | L38: =IF(K38=J38,"coinciden",IF(K38=0,"Nuevo","Discrepan")) -> coinciden
A39: {37 | B39: Burton | C39: =IF(ISERROR(LOOKUP(2^15,SEARCH(B39,'2023'!$B$3:$B$1734,1),'2023'!$A$3:$A$1734)),"NO","SI") -> NO | D39: =IF(ISERROR(LOOKUP(2^15,SEARCH(B39,'2022'!$B$2:$B$1591,1),'2022'!$A$2:$A$1591)),"NO","SI") -> NO | E39: =IF(ISERROR(LOOKUP(2^15,SEARCH(B39,'2021'!$B$2:$B$1494,1),'2021'!$A$2:$A$1494)),"NO","SI") -> NO | F39: =IF(ISERROR(LOOKUP(2^15,SEARCH(B39,'2020'!$B$2:$B$1278,1),'2020'!$A$2:$A$1278)),"NO","SI") -> NO | G39: =IF(ISERROR(LOOKUP(2^15,SEARCH(B39,'2019'!$B$2:$B$1108,1),'2019'!$A$2:$A$1108)),"NO","SI") -> NO | H39: =IF(ISERROR(LOOKUP(2^15,SEARCH(B39,'2018'!$B$1:$B$1047,1),'2018'!$A$1:$A$1047)),"NO","SI") -> NO | I39: =IF(ISERROR(LOOKUP(2^15,SEARCH(B39,'ALERTA SANITARIA'!$B$2:$B$269,1),'2018'!$A$1:$A$1047)),"NO","SI") -> SI | J39: =IF(AND(C39="NO", I39="NO"), "Ninguno",IF(AND(C39="NO", I39="SI"), "COFEPRIS",IF(AND(C39="SI",I39="NO"),"DOF","AMBOS"))) -> COFEPRIS | K39: {=IFERROR(INDEX(Anterior!$C$1:$D$323,MATCH(B39,Anterior!$B$2:$B$323,0)+1,2),0)} -> COFEPRIS | L39: =IF(K39=J39,"coinciden",IF(K39=0,"Nuevo","Discrepan")) -> coinciden
A40: {38 | B40: Caesar Park | C40: =IF(ISERROR(LOOKUP(2^15,SEARCH(B40,'2023'!$B$3:$B$1734,1),'2023'!$A$3:$A$1734)),"NO","SI") -> NO | D40: =IF(ISERROR(LOOKUP(2^15,SEARCH(B40,'2022'!$B$2:$B$1591,1),'2022'!$A$2:$A$1591)),"NO","SI") -> NO | E40: =IF(ISERROR(LOOKUP(2^15,SEARCH(B40,'2021'!$B$2:$B$1494,1),'2021'!$A$2:$A$1494)),"NO","SI") -> NO | F40: =IF(ISERROR(LOOKUP(2^15,SEARCH(B40,'2020'!$B$2:$B$1278,1),'2020'!$A$2:$A$1278)),"NO","SI") -> NO | G40: =IF(ISERROR(LOOKUP(2^15,SEARCH(B40,'2019'!$B$2:$B$1108,1),'2019'!$A$2:$A$1108)),"NO","SI") -> NO | H40: =IF(ISERROR(LOOKUP(2^15,SEARCH(B40,'2018'!$B$1:$B$1047,1),'2018'!$A$1:$A$1047)),"NO","SI") -> NO | I40: =IF(ISERROR(LOOKUP(2^15,SEARCH(B40,'ALERTA SANITARIA'!$B$2:$B$269,1),'2018'!$A$1:$A$1047)),"NO","SI") -> SI | J40: =IF(AND(C40="NO", I40="NO"), "Ninguno",IF(AND(C40="NO", I40="SI"), "COFEPRIS",IF(AND(C40="SI",I40="NO"),"DOF","AMBOS"))) -> COFEPRIS | K40: {=IFERROR(INDEX(Anterior!$C$1:$D$323,MATCH(B40,Anterior!$B$2:$B$323,0)+1,2),0)} -> COFEPRIS | L40: =IF(K40=J40,"coinciden",IF(K40=0,"Nuevo","Discrepan")) -> coinciden
A41: {39 | B41: Camel | C41: =IF(ISERROR(LOOKUP(2^15,SEARCH(B41,'2023'!$B$3:$B$1734,1),'2023'!$A$3:$A$1734)),"NO","SI") -> SI | D41: =IF(ISERROR(LOOKUP(2^15,SEARCH(B41,'2022'!$B$2:$B$1591,1),'2022'!$A$2:$A$1591)),"NO","SI") -> SI | E41: =IF(ISERROR(LOOKUP(2^15,SEARCH(B41,'2021'!$B$2:$B$1494,1),'2021'!$A$2:$A$1494)),"NO","SI") -> SI | F41: =IF(ISERROR(LOOKUP(2^15,SEARCH(B41,'2020'!$B$2:$B$1278,1),'2020'!$A$2:$A$1278)),"NO","SI") -> SI | G41: =IF(ISERROR(LOOKUP(2^15,SEARCH(B41,'2019'!$B$2:$B$1108,1),'2019'!$A$2:$A$1108)),"NO","SI") -> SI | H41: =IF(ISERROR(LOOKUP(2^15,SEARCH(B41,'2018'!$B$1:$B$1047,1),'2018'!$A$1:$A$1047)),"NO","SI") -> SI | I41: =IF(ISERROR(LOOKUP(2^15,SEARCH(B41,'ALERTA SANITARIA'!$B$2:$B$269,1),'2018'!$A$1:$A$1047)),"NO","SI") -> NO | J41: =IF(AND(C41="NO", I41="NO"), "Ninguno",IF(AND(C41="NO", I41="SI"), "COFEPRIS",IF(AND(C41="SI",I41="NO"),"DOF","AMBOS"))) -> DOF | K41: {=IFERROR(INDEX(Anterior!$C$1:$D$323,MATCH(B41,Anterior!$B$2:$B$323,0)+1,2),0)} -> DOF | L41: =IF(K41=J41,"coinciden",IF(K41=0,"Nuevo","Discrepan")) -> coinciden
...

Sheet 2018
A1: 55005 | B1: “GD”
A2: 446006 | B2: Abam Churchills 48 x 7’’
A3: 446008 | B3: Abam Coronas 43 x 6’’
A4: 446009 | B4: Abam Doble Corona 50 x 8’’
A5: 446012 | B5: Abam Entreatos 43 x 4’’
A6: 446011 | B6: Abam Gran Corona “A” 47 x 9 ¼’’
A7: 446016 | B7: Abam Lanceros 38 x 7 ½”
A8: 446010 | B8: Abam Marevas 42 x 5’’
A9: 446017 | B9: Abam Piccolinos
A10: 446015 | B10: Abam Reserva Especial 50 x 6 ½”
A11: 446007 | B11: Abam Robustos 50 x 5’’
A12: 446014 | B12: Abam Short Perfect 54 x 5 ¼” Naturales
... A1047: 209018 | B1047: Zino

Sheet 2019
A1: CLAVES | B1: MARCAS
A2: 1001 | B2: Lucky Strike 1916 C.S.
A3: 1006 | B3: Kent Wallet White C.F.
A4: 1008 | B4: Pall Mall Menthol C.F.
A5: 1010 | B5: Dunhill King Size C.D.
A6: 1013 | B6: Pall Mall 25´s Rojos C.F.
A7: 1014 | B7: Camel 14´s C.D.
A8: 1015 | B8: Camel C.D.
A9: 1016 | B9: Camel Smooth C.D.
A10: 1017 | B10: Salem C.D.
A11: 1018 | B11: Salem 83 M.M. C.D.
A12: 1019 | B12: Raleigh con Filtro
A13: 1020 | B13: Camel Natural F.F.
... A1108: 57002 | B1108: Rancher

Sheet 2020
A1: CLAVES | B1: MARCAS
A2: 1001 | B2: Lucky Strike 1916 C.S.
A3: 1006 | B3: Kent Wallet White C.F.
A4: 1008 | B4: Pall Mall Menthol C.F.
A5: 1010 | B5: Dunhill King Size C.D.
A6: 1013 | B6: Pall Mall 25´s Rojos C.F.
A7: 1014 | B7: Camel 14´s C.D.
A8: 1015 | B8: Camel C.D.
A9: 1016 | B9: Camel Smooth C.D.
A10: 1017 | B10: Salem C.D.
A11: 1018 | B11: Salem 83 M.M. C.D.
A12: 1019 | B12: Raleigh con Filtro
A13: 1020 | B13: Camel Natural F.F.
... A1278: 262003 | B1278: Perdomo

Sheet 2021
A1: CLAVES | B1: MARCAS
A2: 1006 | B2: Kent Wallet White C.F.
A3: 1026 | B3: Montana C.D.
A4: 1028 | B4: Montana Shots F.F.
A5: 1097 | B5: Kent Gold One H.L.
A6: 1100 | B6: Pall Mall Exactos 25´s F.F. C.S.
A7: 1101 | B7: Pall Mall Exactos F.F. C.S.
A8: 1102 | B8: Pall Mall Exactos Lights C.S.
A9: 1103 | B9: Pall Mall Special Lights 100´s C.D.
A10: 1108 | B10: Montana Shots 14´s
A11: 1109 | B11: Montana Shots F.F. 25´s
A12: 1118 | B12: Pall Mall XL Fresh HL
A13: 1119 | B13: Montana 100 FF
... A1494: 59003 | B1494: Daytona

Sheet 2022
A1: CLAVES | B1: MARCAS
A2: 1006 | B2: Kent Wallet White C.F.
A3: 1026 | B3: Montana C.D.
A4: 1028 | B4: Montana Shots F.F.
A5: 1097 | B5: Kent Gold One H.L.
A6: 1100 | B6: Pall Mall Exactos 25´s F.F. C.S.
A7: 1101 | B7: Pall Mall Exactos F.F. C.S.
A8: 1102 | B8: Pall Mall Exactos Lights C.S.
A9: 1103 | B9: Pall Mall Special Lights 100´s C.D.
A10: 1108 | B10: Montana Shots 14´s
A11: 1109 | B11: Montana Shots F.F. 25´s
A12: 1118 | B12: Pall Mall XL Fresh HL
A13: 1119 | B13: Montana 100 FF
... A1591: 462013 | B1591: Acid

Sheet 2023
A1: 55005 | B1: “GD”
A2: 446006 | B2: Abam Churchills 48 x 7’’
A3: 446008 | B3: Abam Coronas 43 x 6’’
A4: 446009 | B4: Abam Doble Corona 50 x 8’’
A5: 446012 | B5: Abam Entreatos 43 x 4’’
A6: 446011 | B6: Abam Gran Corona “A” 47 x 9 ¼’’
A7: 446016 | B7: Abam Lanceros 38 x 7 ½”
A8: 446010 | B8: Abam Marevas 42 x 5’’
A9: 446017 | B9: Abam Piccolinos
A10: 446015 | B10: Abam Reserva Especial 50 x 6 ½”
A11: 446007 | B11: Abam Robustos 50 x 5’’
A12: 446014 | B12: Abam Short Perfect 54 x 5 ¼” Naturales
... A946: 32110 | B946: Marboro Mild 14´s
A947: CLAVES | B947: MARCAS
A948: 208021 | B948: Mariachi
A949: 32226 | B949: Marlboro (Red 2.5) 100 Box
A950: 32256 | B950: Marlboro (Red 2.5) 100 Box 20 STD | Viva MX
A951: 32255 | B951: Marlboro (Red 2.5) LS Box 20 STD | Viva MX
A952: 32207 | B952: Marlboro (Red FWD Caps) 100 Box 20
A953: 32175 | B953: Marlboro (Red Upgrade) LS Box 18
A954: 32031 | B954: Marlboro 100
A955: 32011 | B955: Marlboro 14’s
A956: 32183 | B956: Marlboro Advance KS Box 20
A957: 32206 | B957: Marlboro Amber Advance 100 Box 20
A958: 32124 | B958: Marlboro Black Freeze MNT Ks Box
A959: 32261 | B959: Marlboro Blossom Mist 100 Box 20 STD
... A1733: 409044 | B1733: Zino

Sheet ALERTA SANITARIA
B2: 90210
B3: Ace Club
B4: Admiral
B5: After hours
B6: After the City Dark
B7: Alamo
B8: Amsterdam
B9: Anchor
B10: Aristocrat
B11: Armada
B12: Ashford Blue
B13: Aura emotions
B14: Avalon S
... B203: Razor
B204: Razor azul | C204: Se agregó en revisión Belén: 3 de julio (después de últ rev Khayr)
B205: Red Smoke
B206: Reef
B207: Regular
B208: Rey
B209: Richman Royal
B210: Rock
B211: Roman
B212: Romantic
B213: Rose
B214: Royal
B215: Royal Club
B216: Royal Trident
... B239: Speed
B240: Speedway | C240: Se agregó en revisión Belén: 3 de julio (después de últ rev Khayr)
B241: STERLING EXVCLUSIVE EDITION
B242: Strand
B243: SunCity Menthol
B244: Supreme
B245: Swift
B246: Tiger
B247: Tijuana
B248: Top 20
B249: Trident
B250: Trotter
B251: Troy
...

Sheet Anterior
A1: Consecutivo | B1: Marca | C1: Legal/Ilegal | D1: Ubicación | E1: Fecha de publicación de alerta | F1: Fecha de publicación de RMF | G1: GATS 2009 | H1: ENA 2011 | I1: GATS 2015 | J1: ENCODAT 2016
A2: 1 | B2: Ace Club | C2: Ilegal | D2: COFEPRIS | E2: 43252 | G2: 0 | H2: 0 | I2: 0 | J2: 0
A3: 2 | B3: Admiral | C3: Ilegal | D3: COFEPRIS | E3: 43252 | G3: 0 | H3: 0 | I3: 0 | J3: 0
A4: 3 | B4: After hours | C4: Ilegal | D4: COFEPRIS | E4: 43252 | G4: 0 | H4: 0 | I4: 0 | J4: 0
A5: 4 | B5: Alamo | C5: Ilegal | D5: COFEPRIS | E5: 43252 | G5: 0 | H5: 0 | I5: 1 | J5: 1
A6: 5 | B6: Alas | C6: Legal | D6: DOF | F6: 40026 | G6: 0 | H6: 1 | I6: 1 | J6: 1
A7: 6 | B7: Amsterdam | C7: Ilegal | D7: COFEPRIS | E7: 43252 | G7: 1 | H7: 0 | I7: 0 | J7: 0
A8: 7 | B8: Anchor | C8: Ilegal | D8: COFEPRIS | E8: 43252 | G8: 0 | H8: 0 | I8: 0 | J8: 0
A9: 8 | B9: Aristocrat | C9: Ilegal | D9: COFEPRIS | E9: 43252 | G9: 0 | H9: 0 | I9: 0 | J9: 0
A10: 9 | B10: Armada | C10: Ilegal | D10: COFEPRIS | E10: 43252 | G10: 0 | H10: 0 | I10: 0 | J10: 0
A11: 10 | B11: Asford Blue | C11: Ilegal | D11: Ninguno | G11: 0 | H11: 0 | I11: 0 | J11: 0
A12: 11 | B12: AX Full Flavor | C12: Ilegal | D12: COFEPRIS | E12: 43252 | G12: 0 | H12: 0 | I12: 0 | J12: 0
A13: 12 | B13: Baronet | C13: Legal | D13: DOF | F13: 40026 | G13: 0 | H13: 0 | I13: 1 | J13: 1
A14: 13 | B14: B&B (Bull & Bears) | C14: Ilegal | D14: COFEPRIS | E14: 43252 | G14: 0 | H14: 0 | I14: 0 | J14: 0
A15: 14 | B15: B&J | C15: Ilegal | D15: COFEPRIS | E15: 43252 | G15: 0 | H15: 0 | I15: 0 | J15: 0
A16: 15 | B16: Benson & Hedges | C16: Legal | D16: DOF | F16: 40026 | G16: 1 | H16: 1 | I16: 1 | J16: 1
A17: 16 | B17: Bentley | C17: Ilegal | D17: COFEPRIS | E17: 43252 | G17: 0 | H17: 0 | I17: 0 | J17: 0
A18: 17 | B18: Biasha Nise | C18: Ilegal | D18: COFEPRIS | E18: 43252 | G18: 0 | H18: 0 | I18: 0 | J18: 0
A19: 18 | B19: Big Chief | C19: Ilegal | D19: COFEPRIS | E19: 43252 | G19: 0 | H19: 0 | I19: 0 | J19: 0
A20: 19 | B20: Birmingham | C20: Ilegal | D20: COFEPRIS | E20: 43252 | G20: 0 | H20: 0 | I20: 0 | J20: 0
A21: 20 | B21: Black and White | C21: Ilegal | D21: COFEPRIS | E21: 43252 | G21: 0 | H21: 0 | I21: 0 | J21: 0
A22: 21 | B22: Black Jack | C22: Ilegal | D22: Ambos | F22: 23/12/2015 para 2016 | G22: 0 | H22: 0 | I22: 0 | J22: 1
A23: 22 | B23: Black Horse Stallion | C23: Ilegal | D23: COFEPRIS | E23: 43252 | G23: 0 | H23: 0 | I23: 0 | J23: 0
A24: 23 | B24: Blend Type Box | C24: Ilegal | D24: COFEPRIS | E24: 43252 | G24: 0 | H24: 0 | I24: 0 | J24: 0
A25: 24 | B25: Blitz | C25: Ilegal | D25: COFEPRIS | E25: 43252 | G25: 0 | H25: 0 | I25: 0 | J25: 0
A26: 25 | B26: Blue River | C26: Ilegal | D26: COFEPRIS | E26: 43252 | G26: 0 | H26: 0 | I26: 1 | J26: 1
A27: 26 | B27: Bohemios | C27: Legal | D27: DOF | F27: 40026 | G27: 0 | H27: 0 | I27: 1 | J27: 1
A28: 27 | B28: Boaz | C28: Ilegal | D28: COFEPRIS | E28: 43252 | G28: 0 | H28: 0 | I28: 0 | J28: 0
A29: 28 | B29: Boots | C29: Legal | D29: DOF | F29: 40026 | G29: 1 | H29: 1 | I29: 1 | J29: 1
A30: 29 | B30: Brass | C30: Ilegal | D30: COFEPRIS | E30: 43252 | G30: 0 | H30: 0 | I30: 0 | J30: 1
A31: 30 | B31: Bright | C31: Ilegal | D31: COFEPRIS | E31: 43252 | G31: 0 | H31: 0 | I31: 0 | J31: 1
A32: 31 | B32: Bronco | C32: Ilegal | D32: COFEPRIS | E32: 43252 | G32: 0 | H32: 0 | I32: 0 | J32: 0
A33: 32 | B33: Buffalo | C33: Ilegal | D33: COFEPRIS | E33: 43252 | G33: 0 | H33: 0 | I33: 0 | J33: 0
A34: 33 | B34: Bulls eye | C34: Ilegal | D34: COFEPRIS | E34: 43252 | G34: 0 | H34: 0 | I34: 0 | J34: 0
A35: 34 | B35: Bulls | C35: Ilegal | D35: COFEPRIS | E35: 43252 | G35: 0 | H35: 0 | I35: 0 | J35: 0
A36: 35 | B36: Burton | C36: Ilegal | D36: COFEPRIS | E36: 43252 | G36: 0 | H36: 0 | I36: 0 | J36: 0
A37: 36 | B37: Caesar Park | C37: Ilegal | D37: COFEPRIS | E37: 43252 | G37: 0 | H37: 0 | I37: 0 | J37: 0
A38: 37 | B38: Camel | C38: Legal | D38: DOF | F38: 40026 | G38: 1 | H38: 1 | I38: 1 | J38: 1
A39: 38 | B39: Capital | C39: Ilegal | D39: COFEPRIS | E39: 43252 | G39: 0 | H39: 0 | I39: 0 | J39: 0
A40: 39 | B40: Capri | C40: Ilegal | D40: COFEPRIS | E40: 43252 | G40: 0 | H40: 1 | I40: 0 | J40: 1
...
